<?xml version="1.0"?>
<robot xmlns:xacro="http://www.ros.org/wiki/xacro" xmlns:ignition="http://gazebosim.org/schema">

  <xacro:property name="wheel_radius" value="0.05"/>
  <xacro:property name="wheel_width" value="0.075"/>
  <xacro:property name="wheel_mass" value="1.0"/>

  <xacro:macro name="mecanum_wheel" params="prefix side x_reflect y_reflect">

    <link name="${prefix}${side}_wheel_link">
      <visual>
        <origin xyz="0 0 0" rpy="${-pi/2} 0 0"/>
        <geometry>
          <cylinder radius="${wheel_radius}" length="${wheel_width}"/>
        </geometry>
        <material name="orange">
          <color rgba="1.0 0.4 0.0 1.0"/>
        </material>
      </visual>

      <collision>
        <origin xyz="0 0 0" rpy="${-pi/2} 0 0"/>
        <geometry>
          <cylinder radius="${wheel_radius}" length="${wheel_width}"/>
        </geometry>
      </collision>

      <inertial>
        <origin xyz="0 0 0" rpy="0 0 0"/>
        <mass value="${wheel_mass}"/>
        <inertia
          ixx="${(wheel_mass/12.0) * (3*wheel_radius*wheel_radius + wheel_width*wheel_width)}" ixy="0" ixz="0"
          iyy="${(wheel_mass/2.0) * (wheel_radius*wheel_radius)}" iyz="0"
          izz="${(wheel_mass/12.0) * (3*wheel_radius*wheel_radius + wheel_width*wheel_width)}"/>
      </inertial>
    </link>

    <joint name="${prefix}${side}_wheel_joint" type="continuous">
      <axis xyz="0 1 0"/>
      <parent link="${prefix}base_link"/>
      <child link="${prefix}${side}_wheel_link"/>
      <origin xyz="${x_reflect*0.237} ${y_reflect*0.150} 0.02" rpy="0 0 0"/>
    </joint>

    <gazebo reference="${prefix}${side}_wheel_link">
      <surface>
        <friction>
          <ode>
              <mu>1.0</mu>
              <mu2>1.0</mu2>
              <fdir1>${x_reflect} ${y_reflect} 0</fdir1>
          </ode>
        </friction>
      </surface>
      <visual>
        <material>
          <ambient>1.0 0.4 0.0 1.0</ambient>
          <diffuse>1.0 0.4 0.0 1.0</diffuse>
          <specular>0.2 0.2 0.2 1.0</specular>
          <emissive>0.0 0.0 0.0 0.0</emissive>
        </material>
      </visual>
    </gazebo>

  </xacro:macro>

</robot>
