<?xml version="1.0"?>
<robot xmlns:xacro="http://www.ros.org/wiki/xacro">

  <!-- Especificações das rodas mecanum do robô Caramelo -->
  <xacro:property name="wheel_radius" value="0.05" />
  <xacro:property name="wheel_width" value="0.061" />
  <xacro:property name="wheel_mass" value="3.0" />
  <xacro:property name="wheel_separation" value="0.370" />
  <xacro:property name="wheel_base" value="0.470" />

  <xacro:macro name="mecanum_wheel" params="prefix side x_reflect y_reflect">
    <link name="${prefix}${side}_wheel_link">
      <!-- Geometria visual: roda como cilindro -->
      <visual>
        <origin xyz="0 0 0" rpy="0 0 0"/>
        <geometry>
          <cylinder radius="${wheel_radius}" length="${wheel_width}"/>
        </geometry>
        <material name="wheel_material">
          <color rgba="0.8 0.8 0.0 1.0"/>
        </material>
      </visual>

      <!-- Geometria de colisão: cilindro simples para otimização de performance -->
      <collision>
        <origin xyz="0 0 0" rpy="${pi/2} 0 0"/>
        <geometry>
          <cylinder radius="${wheel_radius}" length="${wheel_width}"/>
        </geometry>
      </collision>

      <!-- Propriedades inerciais baseadas no cilindro -->
      <inertial>
        <origin xyz="0 0 0" rpy="0 0 0"/>
        <mass value="${wheel_mass}"/>
        <inertia
          ixx="${(wheel_mass/12.0) * (3*wheel_radius*wheel_radius + wheel_width*wheel_width)}" ixy="0" ixz="0"
          iyy="${(wheel_mass/2.0) * (wheel_radius*wheel_radius)}" iyz="0"
          izz="${(wheel_mass/12.0) * (3*wheel_radius*wheel_radius + wheel_width*wheel_width)}"/>
      </inertial>
    </link>

    <!-- Joint da roda: rotação contínua em torno do eixo Y -->
    <joint name="${prefix}${side}_wheel_joint" type="continuous">
      <axis xyz="0 1 0"/>
      <parent link="${prefix}base_link"/>
      <child link="${prefix}${side}_wheel_link"/>
      <origin xyz="${x_reflect*(wheel_base/2)} ${y_reflect*(wheel_separation/2)} 0" rpy="0 0 0"/>
    </joint>

    <!-- Configurações específicas do Gazebo para as rodas mecanum -->
    <gazebo reference="${prefix}${side}_wheel_link">
      <material>Gazebo/DarkGrey</material>
      <!-- Propriedades de fricção básicas - configuração simplificada -->
      <mu1>1.0</mu1>
      <mu2>1.0</mu2>
    </gazebo>

  </xacro:macro>
</robot>
